<?xml version="1.0"?>
<robot xmlns:xacro="http://ros.org/wiki/xacro" name="prius">
  <!--- Surface properties must come first? -->
  <gazebo reference="front_left_wheel">
    <mu1>0.9</mu1>
    <mu2>0.9</mu2>
    <minDepth>0.005</minDepth>
    <kp>1e8</kp>
  </gazebo>
  <gazebo reference="front_right_wheel">
    <mu1>0.9</mu1>
    <mu2>0.9</mu2>
    <minDepth>0.005</minDepth>
    <kp>1e8</kp>
  </gazebo>
  <gazebo reference="rear_left_wheel">
    <mu1>0.9</mu1>
    <mu2>0.9</mu2>
    <minDepth>0.005</minDepth>
    <kp>1e8</kp>
  </gazebo>
  <gazebo reference="rear_right_wheel">
    <mu1>0.9</mu1>
    <mu2>0.9</mu2>
    <minDepth>0.005</minDepth>
    <kp>1e8</kp>
  </gazebo>


  <link name="base_link">
    <inertial>
      <mass value="1356.0"/>
      <origin xyz="0 0 0.48" rpy="0 0 1.5708"/>
      <inertia ixx="2581.13354740" ixy="0.0" ixz="0.0" iyy="591.30846112" iyz="0.0" izz="2681.95008628"/>
    </inertial>
    <visual>
      <origin xyz="0 0.05 0.4" rpy="0 0 0"/>
      <geometry>
        <box size="0.05 2.1 0.05"/>
      </geometry>
      <!-- <geometry>
        <mesh filename="package://vehicle_sim/meshes/hybrid_body.obj" scale="0.01 0.01 0.01"/>
      </geometry> -->
    </visual>

    <collision name="base_link">
      <origin xyz="0.0 0.05 0.4" rpy="0 0 0"/>
      <geometry>
        <!-- <box size="1.7526 2.1 0.95"/> -->
        <box size="0.05 2.1 0.05"/>
      </geometry>
    </collision>    
  </link>

  <!-- <link name="tank">
    <inertial>
      <mass value="138.0"/>
      <origin xyz="0 0 0" rpy="0 0 0"/>
      <inertia ixx="25.13354740" ixy="0.0" ixz="0.0" iyy="5.30846112" iyz="0.0" izz="26.95008628"/>
    </inertial>
    <visual>
      <origin xyz="0 0 0" rpy="0 0 0"/>
      <geometry>
        <box size="1 2.1 0.05"/>
      </geometry>
    </visual>
  </link>

  <joint name="tank_joint" type="fixed">
    <origin xyz="0 0 0.15" rpy="0 0 0"/>
    <parent link="base_link"/>
    <child link="tank"/>
  </joint> -->
    <!-- <link name="caster_left_link">
    <visual>
      <origin xyz="0 0 0" rpy="0 0 0" />
      <geometry>
	      <sphere radius="0.1" />
      </geometry>
    </visual>   
    <collision>
      <geometry>
	      <sphere radius="0.1" />
      </geometry>
      <origin xyz="0 0 0" rpy="0 0 0" />
    </collision>        
      <inertial>
        <mass value="100" />
        <origin xyz="0 0 0" />
        <inertia ixx="0.001" ixy="0.0" ixz="0.0"
                 iyy="0.001" iyz="0.0" 
                 izz="0.001" />
      </inertial>
    </link>
 <joint name="caster_left_joint" type="fixed">
      <parent link="base_link"/>
      <child link="caster_left_link"/>
      <origin xyz="1 0.0 0.105" rpy="0 0 0"/>
    </joint>

  <link name="caster_right_link">
    <visual>
      <origin xyz="0 0 0" rpy="0 0 0" />
      <geometry>
	      <sphere radius="0.1" />
      </geometry>
    </visual>   
    <collision>
      <geometry>
	      <sphere radius="0.1" />
      </geometry>
      <origin xyz="0 0 0" rpy="0 0 0" />
    </collision>        
      <inertial>
        <mass value="100" />
        <origin xyz="0 0 0" />
        <inertia ixx="0.001" ixy="0.0" ixz="0.0"
                 iyy="0.001" iyz="0.0" 
                 izz="0.001" />
      </inertial>
    </link>
 <joint name="caster_right_joint" type="fixed">
      <parent link="base_link"/>
      <child link="caster_right_link"/>
      <origin xyz="-1 0.0 0.105" rpy="0 0 0"/>
    </joint> -->


  <link name="fl_axle">
    <inertial>
      <mass value="1"/>
      <origin xyz="0 0 0"/>
      <inertia ixx="0.004" ixy="0.0" ixz="0.0" iyy="0.004" iyz="0.0" izz="0.004"/>
    </inertial>
  </link>
  <link name="front_left_wheel">
    <inertial>
      <mass value="11"/>
      <origin xyz="0 0 0"/>
      <inertia ixx="0.58631238" ixy="0.0" ixz="0.0" iyy="0.33552910" iyz="0.0" izz="0.33552910"/>
    </inertial>
    <collision name="front_left_wheel_collision">
      <geometry>
        <sphere radius="0.31265"/>
      </geometry>
    </collision>
    <visual>
      <origin xyz="0 0 0" rpy="0 0 0"/>
      <geometry>
        <mesh filename="package://vehicle_sim/meshes/wheel.obj" scale="0.01 0.01 0.01"/>
      </geometry>
    </visual>
  </link>
 
  <link name="rear_left_wheel">
    <inertial>
      <mass value="11"/>
      <origin xyz="0 0 0"/>
      <inertia ixx="0.58631238" ixy="0.0" ixz="0.0" iyy="0.33552910" iyz="0.0" izz="0.33552910"/>
    </inertial>
    <collision name="rear_left_wheel_collision">
      <geometry>
        <sphere radius="0.31265"/>
      </geometry>
    </collision>
    <visual>
      <origin xyz="0 0 0" rpy="0 0 0"/>
      <geometry>
        <mesh filename="package://vehicle_sim/meshes/wheel.obj" scale="0.01 0.01 0.01"/>
      </geometry>
    </visual>
  </link>


  <joint name="front_left_steer_joint" type="continuous">
    <parent link="base_link"/>
    <child link="fl_axle"/>
    <origin xyz="0 -1.41 0.3" rpy="0 0 0"/>
    <axis xyz="0 0 1"/>
    <limit lower="-0.8727" upper="0.8727" effort="10000000" velocity="1000000"/>
  </joint>

  <joint name="front_left_wheel_joint" type="continuous">
    <parent link="fl_axle"/>
    <child link="front_left_wheel"/>
    <origin xyz="0 0 0" rpy="0 0 0"/>
    <axis xyz="1 0 0"/>
  </joint>

  <joint name="rear_left_wheel_joint" type="continuous">
    <parent link="base_link"/>
    <child link="rear_left_wheel"/>
    <origin xyz="0 1.45 0.3" rpy="0 0 0"/>
    <axis xyz="1 0 0"/>
  </joint>

  <link name="steering_wheel">
    <inertial>
      <mass value="1.0"/>
      <inertia ixx="0.14583300" ixy="0.0" ixz="0.0" iyy="0.14583300" iyz="0.0" izz="0.125"/>
    </inertial>
    <visual>
      <origin xyz="0 0 0" rpy="1.302101 0 0"/>
      <geometry>
        <mesh filename="package://vehicle_sim/meshes/steering_wheel.obj" scale="0.01 0.01 0.01"/>
      </geometry>
    </visual>
  </link>

  <joint name="steering_joint" type="continuous">
    <origin xyz="0 0 0.988243" rpy="-1.302101 0 0"/>
    <parent link="base_link"/>
    <child link="steering_wheel"/>
    <axis xyz="0 0 1"/>
    <limit lower="-7.85" upper="7.85" effort="10000000" velocity="1000000"/>
  </joint>



  <gazebo>
    <plugin name="pruis_hybrid_drive" filename="libControlHybridPlugin_2w.so">
      <chassis>base_link</chassis>
      <front_left_wheel>front_left_wheel_joint</front_left_wheel>
      <!-- <front_right_wheel>front_right_wheel_joint</front_right_wheel> -->
      <front_left_wheel_steering>front_left_steer_joint</front_left_wheel_steering>
      <!-- <front_right_wheel_steering>front_right_steer_joint</front_right_wheel_steering> -->
      <back_left_wheel>rear_left_wheel_joint</back_left_wheel>
      <!-- <back_right_wheel>rear_right_wheel_joint</back_right_wheel> -->
      <steering_wheel>steering_joint</steering_wheel>
      <chassis_aero_force_gain>0.63045</chassis_aero_force_gain>
      <front_torque>859.4004393000001</front_torque>
      <back_torque>0</back_torque>
      <front_brake_torque>1031.28052716</front_brake_torque>
      <back_brake_torque>687.5203514400001</back_brake_torque>
      <max_speed>37.998337013956565</max_speed>
      <min_gas_flow>8.981854013171626e-05</min_gas_flow>
      <gas_efficiency>0.371</gas_efficiency>
      <battery_charge_watt_hours>291</battery_charge_watt_hours>
      <battery_discharge_watt_hours>214</battery_discharge_watt_hours>
      <max_steer>0.6458</max_steer>
      <flwheel_steering_p_gain>1e4</flwheel_steering_p_gain>
      <!-- <frwheel_steering_p_gain>1e4</frwheel_steering_p_gain> -->
      <flwheel_steering_i_gain>0</flwheel_steering_i_gain>
      <!-- <frwheel_steering_i_gain>0</frwheel_steering_i_gain> -->
      <flwheel_steering_d_gain>3e2</flwheel_steering_d_gain>
      <!-- <frwheel_steering_d_gain>3e2</frwheel_steering_d_gain> -->
    </plugin>
  </gazebo>

  <gazebo>
    <plugin name="joint_state_publisher" filename="libgazebo_ros_joint_state_publisher.so">
      <!-- <robotNamespace>/prius</robotNamespace> -->
      <jointName>rear_left_wheel_joint, front_left_wheel_joint, front_left_steer_joint, steering_joint</jointName>
      <updateRate>100.0</updateRate>
      <alwaysOn>true</alwaysOn>
    </plugin>
  </gazebo>

  <gazebo>
    <plugin name="p3d" filename="libgazebo_ros_p3d.so">
      <!-- <robotNamespace>/prius</robotNamespace> -->
      <bodyName>base_link</bodyName>
      <topicName>base_pose_ground_truth</topicName>
      <frameName>map</frameName>
      <updateRate>100.0</updateRate>
    </plugin>
  </gazebo>

</robot>
